<mujoco model="ultron">
  <compiler angle="radian" meshdir="../meshes/"/>
  <statistic meansize="0.112067" extent="0.426485" center="-0.0680293 -0.000631462 0.133125"/>
  <option timestep="0.002"/>
  <asset>
    <mesh name="base_link" file="base_link.STL"/>
    <mesh name="link1" file="link1.STL"/>
    <mesh name="link2" file="link2.STL"/>
    <mesh name="link3" file="link3.STL"/>
    <mesh name="link4" file="link4.STL"/>
    <mesh name="link5" file="link5.STL"/>
    <mesh name="link6" file="link6.STL"/>
    <texture name="grid" type="2d" builtin="checker" rgb1=".1 .2 .3"
    rgb2=".2 .3 .4" width="300" height="300" />
  <material name="grid" texture="grid" texrepeat="8 8" reflectance=".1" />
  </asset>
  <worldbody>
    <light name="top" pos="0 0 10" castshadow="false" />
    <geom size="10 10 .01" type="plane" material="grid" />
    <geom type="mesh" contype="0" conaffinity="0" group="1" density="0" rgba="0.75294 0.75294 0.75294 1" mesh="base_link"/>
    <body name="link1" pos="0 0 0.0603">
      <inertial pos="0.0060953 -0.0042968 0.017959" quat="0.680193 0.680193 -0.193229 0.193229" mass="0.060835" diaginertia="8.61803e-05 6.38197e-05 3e-05"/>
      <joint name="joint1" pos="0 0 0" axis="0 0 1" range="-1.57 1.57" damping="0.2" frictionloss="0.3"/>
      <geom type="mesh" contype="0" conaffinity="0" group="1" density="0" rgba="0.75294 0.75294 0.75294 1" mesh="link1"/>
      <body name="link2" pos="0.02 0 0.0402">
        <inertial pos="-0.13238 0.0022038 0.00011179" quat="0 0.706195 0 0.708017" mass="1.0733" diaginertia="0.0160201 0.01596 0.000499897"/>
        <joint name="joint2" pos="0 0 0" axis="0 1 0" range="0 3.14" damping="0.2" frictionloss="0.3"/>
        <geom type="mesh" contype="1" conaffinity="1" group="1" density="0" rgba="0.75294 0.75294 0.75294 1" mesh="link2"/>
        <body name="link3" pos="-0.264 0 0" quat="-3.67321e-06 -1 0 0">
          <inertial pos="0.1872 -0.00030568 -0.051483" quat="0.269626 0.618013 0.251786 0.694238" mass="0.4994" diaginertia="0.00388848 0.00385541 0.000286113"/>
          <joint name="joint3" pos="0 0 0" axis="0 1 0" range="0 3.14" damping="0.2" frictionloss="0.3"/>
          <geom type="mesh" contype="0" conaffinity="0" group="1" density="0" rgba="0.75294 0.75294 0.75294 1" mesh="link3"/>
          <body name="link4" pos="0.245 0 -0.056">
            <inertial pos="0.038888 0.0029517 -0.035328" quat="0.707107 0 0 0.707107" mass="0.080971" diaginertia="0.00016 0.00013 0.0001"/>
            <joint name="joint4" pos="0 0 0" axis="0 1 0" range="-1.57 1.57" damping="0.3" frictionloss="0.3"/>
            <geom type="mesh" contype="1" conaffinity="1" group="1" density="0" rgba="0.89804 0.91765 0.92941 1" mesh="link4"/>
            <body name="link5" pos="0.06575 -0.001 -0.0825">
              <inertial pos="0.0028996 3.1583e-05 0.052619" quat="0.998829 0 -0.0483866 0" mass="0.60236" diaginertia="0.000724856 0.00069 0.000205144"/>
              <joint name="joint5" pos="0 0 0" axis="0 0 1" range="-1.57 1.57" damping="0.1" frictionloss="0.1"/>
              <geom type="mesh" contype="1" conaffinity="1" group="1" density="0" rgba="0.75294 0.75294 0.75294 1" mesh="link5"/>
              <body name="link6" pos="0.02845 0 0.0825" quat="-3.67321e-06 -1 0 0">
                <inertial pos="0.0057417 0 0" mass="0.019531" diaginertia="1e-05 1e-05 1e-05"/>
                <joint name="joint6" pos="0 0 0" axis="1 0 0" range="-10 10" damping="0.1" frictionloss="0.1"/>
                <geom type="mesh" contype="0" conaffinity="0" group="1" density="0" rgba="0.89804 0.91765 0.92941 1" mesh="link6"/>
              </body>
            </body>
          </body>
        </body>
      </body>
    </body>
  </worldbody>
</mujoco>
